Workbook

Sheet Regole
A1: DottorScudo TCG — Regole base v0.3
A2: Valori in blu = parametri modificabili. Celle gialle = da confermare.
A4: Regola | B4: Nome a tema | C4: Descrizione | D4: Valore
A5: Risorsa | B5: Caffettini | C5: 1 al primo turno, +1 a turno | D5: 1 → 10
A6: Bonus secondo giocatore | B6: Caffettino extra | C6: Carta usa e getta per chi gioca per secondo | D6: 1
A7: Punti vita eroe | B7: Ore di ferie | C7: A zero ferie si perde (omaggio all'albo #120) | D7: 30
A8: Dimensione mazzo | B8: Mazzo | C8: Carte per mazzo (max 2 copie, 1 per le Leggendarie) | D8: 30
A9: Mano iniziale | B9: Mano | C9: Carte iniziali, con mulligan | D9: 3 / 4
A10: Limite campo | B10: Scrivanie | C10: Massimo servitori per lato | D10: 7
A11: Mazzo esaurito | B11: Burnout | C11: Danni crescenti a ogni pesca a vuoto | D11: 1, 2, 3…
A12: Timer turno | B12: Timer | C12: Secondi per turno (vincolo online) | D12: 75
A13: Fazioni | B13: Ufficio / Soci & Nemici | C13: Ogni eroe usa le carte della sua fazione + le proprie carte firma + le Neutrali | D13: —
A14: Leggendarie | B14: Soci | C14: I soci e i boss sono carte Leggendarie (1 copia per mazzo) | D14: —

Sheet Keyword
A1: Keyword | B1: Equivalente Hearthstone | C1: Effetto
A2: Deploy | B2: Grido di battaglia | C2: Effetto quando la carta viene giocata
A3: Burocrazia | B3: Provocazione | C3: I nemici devono attaccare prima questo servitore
A4: Scudato | B4: Scudo divino | C4: Il primo danno subito viene ignorato
A5: Urgente | B5: Assalto | C5: Può attaccare servitori nel turno in cui entra
A6: Smart working | B6: Furtività | C6: Non può essere bersagliato finché non attacca
A7: Mani in merda | B7: Veleno | C7: Distrugge qualunque servitore a cui infligge danni
A8: Ultimo sorso | B8: Rantolo di morte | C8: Effetto quando il servitore muore
A9: Bloccato in riunione | B9: Congelato | C9: Non può attaccare nel suo prossimo turno
A10: Task | B10: Missione | C10: Obiettivo da completare per ottenere una ricompensa

Sheet Eroi
A1: Eroe | B1: Fazione | C1: Potere eroe | D1: Costo | E1: Effetto | F1: Immagine | G1: Riferimento lore
A2: Dottor Scudo | B2: Ufficio | C2: Alza lo scudo | D2: 2 | E2: Un tuo collega diventa Scudato, oppure ottieni 2 di armatura | F2: avatar-1.jpg | G2: Albi #1, #119
A3: Nikson | B3: Ufficio | C3: Raccogli sassi | D3: 2 | E3: Aggiungi un Sasso alla tua mano | F3: avatar-2.jpg | G3: Albi #3, #6, #25
A4: Jackson | B4: Ufficio | C4: Scoppio d'ira | D4: 2 | E4: Infliggi 1 danno a tutti i servitori nemici e 1 al tuo eroe | F4: avatar-3.jpg (da confermare) | G4: Albo #5
A5: Milet | B5: Ufficio | C5: La via del Giappi | D5: 2 | E5: La prossima Pratica che giochi in questo turno costa 2 in meno | F5: avatar-5.jpg (da confermare) | G5: Albo #4
A6: Ale | B6: Ufficio | C6: Fuga dalla riunione | D6: 2 | E6: Rimanda in mano un tuo collega: costa 1 in meno | F6: da confermare | G6: Albi #10, #11, #12, #28
A7: Il Creatore | B7: Ufficio | C7: Nuova tavola | D7: 2 | E7: Scopri un collega dell'Ufficio (scegline 1 tra 3) e aggiungilo alla tua mano | F7: da confermare | G7: Autore di tutti gli albi (Enriquez da Sosa), tag #SOSA
A8: Dr Grappolo | B8: Soci & Nemici | C8: Lavaggio del cervello | D8: 2 | E8: Evoca uno Studente plagiato 1/1 | F8: avatar-7.jpg (da confermare) | G8: Albi #1, #10
A9: Il Calabrone | B9: Soci & Nemici | C9: Pungiglione | D9: 2 | E9: Infliggi 2 danni all'eroe nemico | F9: da confermare | G9: Albi #31, #51
A10: Lord Capognus | B10: Soci & Nemici | C10: L'esperimento | D10: 2 | E10: Dai +2 attacco a un tuo servitore; subisce 1 danno | F10: da confermare | G10: Albo #24
A12: Gli eroi dell'Ufficio sono i colleghi; la fazione Soci & Nemici ha tre eroi iniziali. Ruoli e avatar vanno confermati.

Sheet Carte
A1: Nome | B1: Fazione | C1: Carta firma di | D1: Rarità | E1: Tipo | F1: Costo | G1: Attacco | H1: Vita / Durabilità | I1: Keyword | J1: Effetto | K1: Riferimento lore | L1: Immagine (sorgente)
A2: Scudo dell'ultimo momento | B2: Ufficio | C2: Dottor Scudo | D2: Rara | E2: Pratica | F2: 1 | J2: Dai Scudato a un collega. Pesca una carta | K2: Albo #119 | L2: albo-119.webp
A3: Scudo Bike | B3: Ufficio | C3: Dottor Scudo | D3: Comune | E3: Strumento | F3: 3 | G3: 3 | H3: 2 | J3: Dopo che il tuo eroe attacca, ottieni 1 armatura | K3: Albo #38 | L3: albo-038.webp
A4: Scudozord | B4: Ufficio | C4: Dottor Scudo | D4: Leggendaria | E4: Collega | F4: 8 | G4: 8 | H4: 8 | I4: Burocrazia, Deploy | J4: Dai Scudato a tutti gli altri tuoi colleghi | K4: Saga Zanzagallo e Sociozilla (#81-86) | L4: albo-081.webp
A5: Sasso | B5: Ufficio | C5: Nikson | D5: Token | E5: Pratica | F5: 0 | J5: Dai +1/+1 a un collega | K5: Albo #6 | L5: albo-006.webp
A6: Uomo Sasso | B6: Ufficio | C6: Nikson | D6: Epica | E6: Collega | F6: 5 | G6: 4 | H6: 6 | I6: Burocrazia, Deploy | J6: +1/+1 per ogni Sasso giocato in questa partita | K6: Albo #3 | L6: albo-003.webp
A7: Serranikson | B7: Ufficio | C7: Nikson | D7: Leggendaria | E7: Collega | F7: 6 | G7: 6 | H7: 5 | I7: Deploy | J7: Distruggi un servitore nemico con 3 o meno attacco | K7: Albo #25 | L7: albo-025.webp
A8: Scoppio d'ira | B8: Ufficio | C8: Jackson | D8: Rara | E8: Pratica | F8: 3 | J8: Infliggi 2 danni a tutti i servitori | K8: Albo #5 | L8: albo-005.webp
A9: Collega furioso | B9: Ufficio | C9: Jackson | D9: Comune | E9: Collega | F9: 4 | G9: 5 | H9: 3 | J9: Quando subisce danni, infligge 1 danno a tutti gli altri servitori | K9: Albo #5 | L9: albo-005.webp
A10: Sushi di fiducia | B10: Ufficio | C10: Milet | D10: Comune | E10: Pratica | F10: 2 | J10: Rigenera 4 ferie. Pesca una carta | K10: Albo #4 | L10: albo-004.webp
A11: Miletta | B11: Ufficio | C11: Milet | D11: Rara | E11: Collega | F11: 2 | G11: 3 | H11: 3 | I11: Ultimo sorso | J11: Evoca uno Spirito zanzara 1/1 per l'avversario | K11: Albi #74, #75 | L11: albo-074.webp
A12: Incatenato alla postazione | B12: Ufficio | C12: Ale | D12: Comune | E12: Pratica | F12: 1 | I12: Bloccato in riunione | J12: Un servitore nemico è Bloccato in riunione | K12: Albi #10-12 | L12: albo-010.webp
A13: Klaudioken | B13: Ufficio | D13: Epica | E13: Pratica | F13: 4 | J13: Infliggi 5 danni | K13: Albi #114, #119 | L13: albo-114.webp
A14: Re Klaudio | B14: Ufficio | D14: Leggendaria | E14: Collega | F14: 7 | G14: 5 | H14: 7 | I14: Deploy | J14: Pesca 2 carte; costano 1 in meno | K14: Albi #111, #115 | L14: albo-111.webp
A15: Portinaio dell'aldilà | B15: Ufficio | D15: Rara | E15: Collega | F15: 3 | G15: 2 | H15: 4 | I15: Ultimo sorso | J15: Riporta in mano un tuo collega morto in questa partita | K15: Albi #111, #115 | L15: albo-115.webp
A16: Bozza a matita | B16: Ufficio | C16: Il Creatore | D16: Comune | E16: Pratica | F16: 1 | J16: Scopri una Pratica dell'Ufficio | K16: Tag #SOSA
A17: Retcon | B17: Ufficio | C17: Il Creatore | D17: Epica | E17: Pratica | F17: 4 | J17: Rimanda tutti i servitori in mano ai rispettivi proprietari | K17: Tag #SOSA
A18: La Lore dell'ufficio | B18: Ufficio | C18: Il Creatore | D18: Leggendaria | E18: Pratica | F18: 6 | J18: Evoca 3 colleghi casuali dell'Ufficio con costo 3 o meno | K18: Saga La Lore dell'ufficio (#1-45) | L18: albo-001.webp
A19: Il Crudo | B19: Ufficio | D19: Rara | E19: Collega | F19: 5 | G19: 4 | H19: 6 | I19: Burocrazia | K19: Albo #2 | L19: albo-002.webp
A20: Super Crudo | B20: Ufficio | D20: Leggendaria | E20: Collega | F20: 8 | G20: 7 | H20: 7 | I20: Deploy | J20: Dai +2/+2 a tutti gli altri tuoi colleghi | K20: Albi #47-49 | L20: albo-047.webp
A21: Scorta di Teresa | B21: Ufficio | D21: Comune | E21: Pratica | F21: 1 | J21: Rigenera 3 ferie | K21: Albi #115, #117 | L21: albo-115.webp
A22: Tatine Mobile | B22: Ufficio | D22: Rara | E22: Strumento | F22: 4 | G22: 3 | H22: 3 | J22: Il tuo eroe può attaccare due volte per turno | K22: Albi #55, #56 | L22: albo-055.webp
A23: Emergenza ritardi | B23: Ufficio | D23: Comune | E23: Pratica | F23: 1 | I23: Urgente | J23: Un collega ottiene Urgente e +1 attacco | K23: Tag #EMERGENZA RITARDI
A24: Ciao Guido, sono Guido | B24: Ufficio | D24: Rara | E24: Pratica | F24: 2 | J24: Evoca una copia 1/1 di un tuo collega | K24: Tag #CIAO GUIDO SONO GUIDO
A25: Il Cursore | B25: Ufficio | D25: Comune | E25: Collega | F25: 2 | G25: 2 | H25: 2 | I25: Deploy | J25: Pesca una carta | K25: Albi #81-83 | L25: albo-081.webp
A26: Le Task | B26: Ufficio | D26: Epica | E26: Pratica | F26: 1 | I26: Task | J26: Gioca 5 Pratiche. Ricompensa: Ferie arretrate (rigenera 10 ferie) | K26: Albi #19, #96, #120 | L26: albo-019.webp
A27: La Zanzara | B27: Soci & Nemici | D27: Leggendaria | E27: Collega | F27: 4 | G27: 3 | H27: 3 | I27: Urgente, Mani in merda | K27: Saga Zanzara e Ragno (#109-120) | L27: albo-120.webp
A28: Il Ragno | B28: Soci & Nemici | D28: Leggendaria | E28: Collega | F28: 4 | G28: 3 | H28: 4 | I28: Deploy | J28: Un collega nemico è Bloccato in riunione per 2 turni | K28: Albi #78, #84, #120 | L28: albo-084.webp
A29: Il Calabrone | B29: Soci & Nemici | D29: Leggendaria | E29: Collega | F29: 7 | G29: 6 | H29: 6 | J29: All'inizio del tuo turno evoca una Zanzarina 1/1 | K29: Saga La tirannia del Calabrone | L29: albo-051.webp
A30: Dr Grappolo | B30: Soci & Nemici | D30: Leggendaria | E30: Collega | F30: 6 | G30: 5 | H30: 5 | I30: Deploy | J30: Evoca due Studenti plagiati 1/1 | K30: Albo #1 | L30: albo-001.webp
A31: Il Grappolaccio | B31: Soci & Nemici | C31: Dr Grappolo | D31: Leggendaria | E31: Collega | F31: 9 | G31: 8 | H31: 8 | I31: Deploy | J31: Infliggi 2 danni a tutti i colleghi nemici | K31: Albi #32, #33, #49 | L31: albo-032.webp
A32: Sociozilla | B32: Soci & Nemici | D32: Leggendaria | E32: Collega | F32: 9 | G32: 8 | H32: 8 | I32: Deploy | J32: Infliggi 2 danni a tutti gli altri servitori | K32: Albi #79-83 | L32: albo-079.webp
A33: Margherita | B33: Soci & Nemici | C33: Dr Grappolo | D33: Epica | E33: Collega | F33: 3 | G33: 2 | H33: 4 | I33: Deploy | J33: Il tuo prossimo Grappolaccio costa 3 in meno | K33: Albo #9 | L33: albo-009.webp
A34: Il Serramanico | B34: Soci & Nemici | D34: Epica | E34: Collega | F34: 4 | G34: 4 | H34: 3 | I34: Smart working | K34: Albo #3 | L34: albo-003.webp
A35: Lord Capognus | B35: Soci & Nemici | C35: Lord Capognus | D35: Leggendaria | E35: Collega | F35: 6 | G35: 3 | H35: 6 | I35: Deploy | J35: Prendi il controllo di un collega nemico con 2 o meno attacco | K35: Albi #24-26 | L35: albo-024.webp
A36: Zanzagallo | B36: Soci & Nemici | D36: Epica | E36: Collega | F36: 5 | G36: 4 | H36: 5 | I36: Burocrazia | J36: Alla fine del tuo turno, infligge 1 danno a tutti i colleghi nemici | K36: Albi #76-78 | L36: albo-076.webp
A37: La Canalis | B37: Soci & Nemici | D37: Rara | E37: Collega | F37: 3 | G37: 2 | H37: 2 | I37: Ultimo sorso | J37: Infliggi 2 danni all'eroe nemico | K37: Albi #63-66 | L37: albo-063.webp
A38: Il Serpentone | B38: Soci & Nemici | D38: Rara | E38: Collega | F38: 6 | G38: 4 | H38: 8 | I38: Burocrazia | K38: Albi #111-114 | L38: albo-111.webp
A39: Sermig: reparto sfruttamento | B39: Soci & Nemici | D39: Rara | E39: Pratica | F39: 3 | J39: I tuoi servitori ottengono +2 attacco e subiscono 1 danno | K39: Albi #7, #62, #64 | L39: albo-062.webp
A40: Troiaio Comunicazioni | B40: Soci & Nemici | D40: Comune | E40: Pratica | F40: 2 | J40: Pesca 2 carte. L'avversario pesca 1 carta | K40: Albi #67-69 | L40: albo-067.webp
...

Sheet Riepilogo
A1: Riepilogo set (si aggiorna dal foglio Carte)
A3: Fazione | B3: Carte giocabili | C3: Costo medio | D3: Colleghi | E3: Pratiche | F3: Strumenti | G3: Leggendarie
A4: Ufficio | B4: =COUNTIF(Carte!$B$2:$B$300,A4)-COUNTIFS(Carte!$B$2:$B$300,A4,Carte!$D$2:$D$300,"Token") -> 24 | C4: =IFERROR((SUMIF(Carte!$B$2:$B$300,A4,Carte!$F$2:$F$300)-SUMIFS(Carte!$F$2:$F$300,Carte!$B$2:$B$300,A4,Carte!$D$2:$D$300,"Token"))/B4,0) -> 3.5 | D4: =COUNTIFS(Carte!$B$2:$B$300,A4,Carte!$E$2:$E$300,"Collega",Carte!$D$2:$D$300,"<>Token") -> 10 | E4: =COUNTIFS(Carte!$B$2:$B$300,A4,Carte!$E$2:$E$300,"Pratica",Carte!$D$2:$D$300,"<>Token") -> 12 | F4: =COUNTIFS(Carte!$B$2:$B$300,A4,Carte!$E$2:$E$300,"Strumento") -> 2 | G4: =COUNTIFS(Carte!$B$2:$B$300,A4,Carte!$D$2:$D$300,"Leggendaria") -> 5
A5: Soci & Nemici | B5: =COUNTIF(Carte!$B$2:$B$300,A5)-COUNTIFS(Carte!$B$2:$B$300,A5,Carte!$D$2:$D$300,"Token") -> 18 | C5: =IFERROR((SUMIF(Carte!$B$2:$B$300,A5,Carte!$F$2:$F$300)-SUMIFS(Carte!$F$2:$F$300,Carte!$B$2:$B$300,A5,Carte!$D$2:$D$300,"Token"))/B5,0) -> 4.6111111 | D5: =COUNTIFS(Carte!$B$2:$B$300,A5,Carte!$E$2:$E$300,"Collega",Carte!$D$2:$D$300,"<>Token") -> 12 | E5: =COUNTIFS(Carte!$B$2:$B$300,A5,Carte!$E$2:$E$300,"Pratica",Carte!$D$2:$D$300,"<>Token") -> 6 | F5: =COUNTIFS(Carte!$B$2:$B$300,A5,Carte!$E$2:$E$300,"Strumento") -> 0 | G5: =COUNTIFS(Carte!$B$2:$B$300,A5,Carte!$D$2:$D$300,"Leggendaria") -> 7
A6: Neutrale | B6: =COUNTIF(Carte!$B$2:$B$300,A6)-COUNTIFS(Carte!$B$2:$B$300,A6,Carte!$D$2:$D$300,"Token") -> 3 | C6: =IFERROR((SUMIF(Carte!$B$2:$B$300,A6,Carte!$F$2:$F$300)-SUMIFS(Carte!$F$2:$F$300,Carte!$B$2:$B$300,A6,Carte!$D$2:$D$300,"Token"))/B6,0) -> 2 | D6: =COUNTIFS(Carte!$B$2:$B$300,A6,Carte!$E$2:$E$300,"Collega",Carte!$D$2:$D$300,"<>Token") -> 0 | E6: =COUNTIFS(Carte!$B$2:$B$300,A6,Carte!$E$2:$E$300,"Pratica",Carte!$D$2:$D$300,"<>Token") -> 3 | F6: =COUNTIFS(Carte!$B$2:$B$300,A6,Carte!$E$2:$E$300,"Strumento") -> 0 | G6: =COUNTIFS(Carte!$B$2:$B$300,A6,Carte!$D$2:$D$300,"Leggendaria") -> 0
A7: Totale | B7: =SUM(B4:B6) -> 45 | C7: =IFERROR(SUMPRODUCT((Carte!$D$2:$D$300<>"Token")*(Carte!$F$2:$F$300))/B7,0) -> 3.8444444 | D7: =SUM(D4:D6) -> 22 | E7: =SUM(E4:E6) -> 21 | F7: =SUM(F4:F6) -> 2 | G7: =SUM(G4:G6) -> 12
A9: I Token (carte generate da altri effetti) sono esclusi dai conteggi. Obiettivo v1: abbastanza carte per mazzi da 30 per ogni eroe.

Sheet Immagini
A1: Sorgenti immagini da dottorscudo.guidomoroni.com/storage
A3: File | B3: Tipo | C3: Personaggio / note
A4: avatar-1.jpg | B4: Avatar personaggio | C4: Dottor Scudo (corrisponde all'eroe in homepage)
A5: avatar-2.jpg | B5: Avatar personaggio | C5: Nikson (cappellino SASSI, avatar del tuo profilo)
A6: avatar-3.jpg | B6: Avatar personaggio | C6: Jackson? (espressione furiosa) — da confermare
A7: avatar-4.jpg | B7: Avatar personaggio | C7: da confermare
A8: avatar-5.jpg | B8: Avatar personaggio | C8: Milet? (elmo da samurai, via del Giappi) — da confermare
A9: avatar-6.jpg | B9: Avatar personaggio | C9: da confermare
A10: avatar-7.jpg | B10: Avatar personaggio | C10: Dr Grappolo? — da confermare
A11: avatar-8.jpg | B11: Avatar personaggio | C11: Margherita? (petali di margherita) — da confermare
A12: fumetti/webp/albo-001 … albo-120.webp | B12: Tavole fumetto (webp) | C12: 120 file, ~19,4 MB totali. Da ritagliare per l'arte delle carte
A13: fumetti/albo-121.png, albo-122.png | B13: Tavole fumetto (png) | C13: Versione webp non disponibile; png ~3 MB l'una
